Workbook

Sheet QA Summary
A1: EduVision 2026 - Module 7 QA Master
A2: Milestone 4 quality evidence for the approved five-dashboard Power BI release | Generated 1 September 2026
A4: TOTAL TESTS | C4: PASSED | E4: FAILED | G4: PASS RATE | I4: RELEASE STATUS
A5: =COUNTA('Test Cases'!$A$6:$A$305) -> 300 | C5: =COUNTIF('Test Cases'!$J$6:$J$305,"PASS") -> 300 | E5: =COUNTIF('Test Cases'!$J$6:$J$305,"FAIL") -> 0 | G5: =IFERROR(C5/A5,0) -> 1 | I5: =IF(E5=0,"APPROVED","BLOCKED") -> APPROVED
A8: APPROVED RELEASE PROFILE
A9: Universities | B9: 1120 | C9: Countries | D9: 93 | E9: Regions | F9: 5 | G9: Reporting Year | H9: 2026 | I9: KPI Accuracy | J9: 1 | K9: Open Critical Defects | L9: 0
A10: Dashboard Pages | B10: 5 | C10: Report Visuals | D10: 110 | E10: Data Visuals | F10: 95 | G10: DAX Measures | H10: 35 | I10: Active Bindings | J10: 310 | K10: Inactive Bindings | L10: 0
A11: KPI Cards | B11: 22 | C11: Slicers | D11: 30 | E11: Navigators | F11: 5 | G11: Standard Maps | H11: 5 | I11: Native Visual Types | J11: 20 | K11: Release ZIP MB | L11: 1.6
A12: Source Completeness | B12: 0.98176 | C12: Cleaned Missingness | D12: 0.015686 | E12: Duplicate Keys | F12: 0 | G12: Machine Path | H12: None | I12: Embedded Import | J12: Yes | K12: Sign-in-gated Visuals | L12: 0
A15: Test Category | B15: Total | C15: Passed | D15: Failed | E15: Pass Rate
A16: Field binding | B16: 98 | C16: 98 | D16: 0 | E16: 1
A17: Dashboard page contract | B17: 60 | C17: 60 | D17: 0 | E17: 1
A18: Map validation | B18: 35 | C18: 35 | D18: 0 | E18: 1
A19: Data quality | B19: 20 | C19: 20 | D19: 0 | E19: 1
A20: KPI reconciliation | B20: 20 | C20: 20 | D20: 0 | E20: 1
A21: User acceptance testing | B21: 20 | C21: 20 | D21: 0 | E21: 1
A22: Final handover | B22: 14 | C22: 14 | D22: 0 | E22: 1
A23: Packaging | B23: 9 | C23: 9 | D23: 0 | E23: 1
A24: Dashboard integration | B24: 9 | C24: 9 | D24: 0 | E24: 1
A25: Semantic model | B25: 8 | C25: 8 | D25: 0 | E25: 1
A26: Documentation | B26: 3 | C26: 3 | D26: 0 | E26: 1
A27: Dashboard compatibility | B27: 2 | C27: 2 | D27: 0 | E27: 1
... A29: Report definition | B29: 1 | C29: 1 | D29: 0 | E29: 1

Sheet Test Cases
A1: Detailed Test Case Register
A2: 300 automated and corroborated UAT checks; every expected and actual result is retained for audit.
A5: Test ID | B5: Requirement ID | C5: Module | D5: Category | E5: Test Scenario | F5: Expected Result | G5: Actual Result | H5: Execution Method | I5: Priority | J5: Status | K5: Evidence
A6: M4-TC-001 | B6: M7-P01 | C6: Module 7 | D6: Packaging | E6: Approved dashboard ZIP exists | F6: present | G6: True | H6: Automated | I6: Critical | J6: PASS | K6: EduVision_PowerBI_Modules_4_to_6_Advanced_5_Dashboards_Standard_Maps_No_SignIn.zip
A7: M4-TC-002 | B7: M7-P02 | C7: Module 7 | D7: Packaging | E7: Approved dashboard ZIP checksum | F7: 98dd2ed7bdae98fabe661d68af729c3cdb8c3f1d5ae097d94492813ba1593a12 | G7: 98dd2ed7bdae98fabe661d68af729c3cdb8c3f1d5ae097d94492813ba1593a12 | H7: Automated | I7: Critical | J7: PASS | K7: SHA-256
A8: M4-TC-003 | B8: M7-P03 | C8: Module 7 | D8: Packaging | E8: ZIP compression integrity | F8: no corrupt member | G8: none | H8: Automated | I8: Critical | J8: PASS | K8: ZipFile.testzip
A9: M4-TC-004 | B9: M7-P04 | C9: Module 7 | D9: Packaging | E9: PBIP entry present in archive | F9: EduVision.pbip | G9: True | H9: Automated | I9: Critical | J9: PASS | K9: ZIP directory
A10: M4-TC-005 | B10: M7-P05 | C10: Module 7 | D10: Packaging | E10: Semantic model present in archive | F10: Universities.tmdl | G10: True | H10: Automated | I10: Critical | J10: PASS | K10: ZIP directory
A11: M4-TC-006 | B11: M7-P06 | C11: Module 7 | D11: Packaging | E11: Report definition present in archive | F11: pages.json | G11: True | H11: Automated | I11: Critical | J11: PASS | K11: ZIP directory
A12: M4-TC-007 | B12: M7-P07 | C12: Module 7 | D12: Packaging | E12: Source workbook included for audit | F12: one Excel workbook | G12: 1 | H12: Automated | I12: High | J12: PASS | K12: ZIP directory
A13: M4-TC-008 | B13: M7-P08 | C13: Module 7 | D13: Packaging | E13: Storyboard included | F13: dashboard_storyboard.pdf | G13: True | H13: Automated | I13: High | J13: PASS | K13: ZIP directory
A14: M4-TC-009 | B14: M7-P09 | C14: Module 7 | D14: Packaging | E14: Beginner opening script included | F14: START_HERE_OPEN_EDUVISION.cmd | G14: True | H14: Automated | I14: High | J14: PASS | K14: ZIP directory
A15: M4-TC-010 | B15: M7-Q01 | C15: Module 7 | D15: Data quality | E15: Raw university records | F15: 1120 | G15: 1120 | H15: Automated | I15: Critical | J15: PASS | K15: REFERENCE_DATA CSV and audit JSON
A16: M4-TC-011 | B16: M7-Q02 | C16: Module 7 | D16: Data quality | E16: Raw source fields | F16: 42 | G16: 42 | H16: Automated | I16: High | J16: PASS | K16: REFERENCE_DATA CSV and audit JSON
... A305: M4-TC-300 | B305: M8-H01 | C305: Module 7 | D305: Final handover | E305: Required deliverable: 00_READ_ME_FIRST.md | F305: present and non-empty | G305: 3796 | H305: Automated | I305: Critical | J305: PASS | K305: 00_READ_ME_FIRST.md

Sheet Requirements Traceability
A1: Requirements Traceability Matrix
A2: Every Milestone 4 requirement is mapped to executed tests and retained evidence.
A5: Requirement ID | B5: Area | C5: Representative Requirement | D5: Test Count | E5: Pass Count | F5: Fail Count | G5: Status | H5: Principal Evidence
A6: M7-A01 | B6: Documentation | C6: Dashboard storyboard exists | D6: =COUNTIF('Test Cases'!$B$6:$B$305,A6) -> 1 | E6: =COUNTIFS('Test Cases'!$B$6:$B$305,A6,'Test Cases'!$J$6:$J$305,"PASS") -> 1 | F6: =COUNTIFS('Test Cases'!$B$6:$B$305,A6,'Test Cases'!$J$6:$J$305,"FAIL") -> 0 | G6: =IF(F6=0,"PASS","FAIL") -> PASS | H6: dashboard_storyboard.pdf
A7: M7-A02 | B7: Documentation | C7: Opening instructions exist | D7: =COUNTIF('Test Cases'!$B$6:$B$305,A7) -> 1 | E7: =COUNTIFS('Test Cases'!$B$6:$B$305,A7,'Test Cases'!$J$6:$J$305,"PASS") -> 1 | F7: =COUNTIFS('Test Cases'!$B$6:$B$305,A7,'Test Cases'!$J$6:$J$305,"FAIL") -> 0 | G7: =IF(F7=0,"PASS","FAIL") -> PASS | H7: approved project folder
A8: M7-A03 | B8: Documentation | C8: Beginner launcher exists | D8: =COUNTIF('Test Cases'!$B$6:$B$305,A8) -> 1 | E8: =COUNTIFS('Test Cases'!$B$6:$B$305,A8,'Test Cases'!$J$6:$J$305,"PASS") -> 1 | F8: =COUNTIFS('Test Cases'!$B$6:$B$305,A8,'Test Cases'!$J$6:$J$305,"FAIL") -> 0 | G8: =IF(F8=0,"PASS","FAIL") -> PASS | H8: approved project folder
A9: M7-D01 | B9: Dashboard page contract | C9: University Overview: correct order | D9: =COUNTIF('Test Cases'!$B$6:$B$305,A9) -> 5 | E9: =COUNTIFS('Test Cases'!$B$6:$B$305,A9,'Test Cases'!$J$6:$J$305,"PASS") -> 5 | F9: =COUNTIFS('Test Cases'!$B$6:$B$305,A9,'Test Cases'!$J$6:$J$305,"FAIL") -> 0 | G9: =IF(F9=0,"PASS","FAIL") -> PASS | H9: pages.json
A10: M7-D02 | B10: Dashboard page contract | C10: University Overview: page width | D10: =COUNTIF('Test Cases'!$B$6:$B$305,A10) -> 5 | E10: =COUNTIFS('Test Cases'!$B$6:$B$305,A10,'Test Cases'!$J$6:$J$305,"PASS") -> 5 | F10: =COUNTIFS('Test Cases'!$B$6:$B$305,A10,'Test Cases'!$J$6:$J$305,"FAIL") -> 0 | G10: =IF(F10=0,"PASS","FAIL") -> PASS | H10: page.json
A11: M7-D03 | B11: Dashboard page contract | C11: University Overview: page height | D11: =COUNTIF('Test Cases'!$B$6:$B$305,A11) -> 5 | E11: =COUNTIFS('Test Cases'!$B$6:$B$305,A11,'Test Cases'!$J$6:$J$305,"PASS") -> 5 | F11: =COUNTIFS('Test Cases'!$B$6:$B$305,A11,'Test Cases'!$J$6:$J$305,"FAIL") -> 0 | G11: =IF(F11=0,"PASS","FAIL") -> PASS | H11: page.json
A12: M7-D04 | B12: Dashboard page contract | C12: University Overview: total visuals | D12: =COUNTIF('Test Cases'!$B$6:$B$305,A12) -> 5 | E12: =COUNTIFS('Test Cases'!$B$6:$B$305,A12,'Test Cases'!$J$6:$J$305,"PASS") -> 5 | F12: =COUNTIFS('Test Cases'!$B$6:$B$305,A12,'Test Cases'!$J$6:$J$305,"FAIL") -> 0 | G12: =IF(F12=0,"PASS","FAIL") -> PASS | H12: visual definitions
A13: M7-D05 | B13: Dashboard page contract | C13: University Overview: dropdown slicers | D13: =COUNTIF('Test Cases'!$B$6:$B$305,A13) -> 5 | E13: =COUNTIFS('Test Cases'!$B$6:$B$305,A13,'Test Cases'!$J$6:$J$305,"PASS") -> 5 | F13: =COUNTIFS('Test Cases'!$B$6:$B$305,A13,'Test Cases'!$J$6:$J$305,"FAIL") -> 0 | G13: =IF(F13=0,"PASS","FAIL") -> PASS | H13: visual definitions
A14: M7-D06 | B14: Dashboard page contract | C14: University Overview: KPI cards | D14: =COUNTIF('Test Cases'!$B$6:$B$305,A14) -> 5 | E14: =COUNTIFS('Test Cases'!$B$6:$B$305,A14,'Test Cases'!$J$6:$J$305,"PASS") -> 5 | F14: =COUNTIFS('Test Cases'!$B$6:$B$305,A14,'Test Cases'!$J$6:$J$305,"FAIL") -> 0 | G14: =IF(F14=0,"PASS","FAIL") -> PASS | H14: card visual definitions
A15: M7-D07 | B15: Dashboard page contract | C15: University Overview: native navigator | D15: =COUNTIF('Test Cases'!$B$6:$B$305,A15) -> 5 | E15: =COUNTIFS('Test Cases'!$B$6:$B$305,A15,'Test Cases'!$J$6:$J$305,"PASS") -> 5 | F15: =COUNTIFS('Test Cases'!$B$6:$B$305,A15,'Test Cases'!$J$6:$J$305,"FAIL") -> 0 | G15: =IF(F15=0,"PASS","FAIL") -> PASS | H15: navigator definition
A16: M7-D08 | B16: Dashboard page contract | C16: University Overview: standard map | D16: =COUNTIF('Test Cases'!$B$6:$B$305,A16) -> 5 | E16: =COUNTIFS('Test Cases'!$B$6:$B$305,A16,'Test Cases'!$J$6:$J$305,"PASS") -> 5 | F16: =COUNTIFS('Test Cases'!$B$6:$B$305,A16,'Test Cases'!$J$6:$J$305,"FAIL") -> 0 | G16: =IF(F16=0,"PASS","FAIL") -> PASS | H16: map definition
A17: M7-D09 | B17: Dashboard page contract | C17: University Overview: no inactive projections | D17: =COUNTIF('Test Cases'!$B$6:$B$305,A17) -> 5 | E17: =COUNTIFS('Test Cases'!$B$6:$B$305,A17,'Test Cases'!$J$6:$J$305,"PASS") -> 5 | F17: =COUNTIFS('Test Cases'!$B$6:$B$305,A17,'Test Cases'!$J$6:$J$305,"FAIL") -> 0 | G17: =IF(F17=0,"PASS","FAIL") -> PASS | H17: queryState projections
... A85: M8-H01 | B85: Final handover | C85: Required deliverable: EduVision_Module_7_QA_Master.xlsx | D85: =COUNTIF('Test Cases'!$B$6:$B$305,A85) -> 14 | E85: =COUNTIFS('Test Cases'!$B$6:$B$305,A85,'Test Cases'!$J$6:$J$305,"PASS") -> 14 | F85: =COUNTIFS('Test Cases'!$B$6:$B$305,A85,'Test Cases'!$J$6:$J$305,"FAIL") -> 0 | G85: =IF(F85=0,"PASS","FAIL") -> PASS | H85: MODULE_07_QA_TESTING/EduVision_Module_7_QA_Master.xlsx; MODULE_07_QA_TESTING/EduVision_Module_7_Detailed_Testing_Report.docx; MODULE_07_QA_TESTING/EduVision_Module_7_Detailed_Testing_Report.pdf

Sheet Data Quality
A1: Data Quality and Integrity Tests
A2: Source completeness, cleaning, duplicate control, year scope, value ranges and non-fabrication controls.
A5: Test ID | B5: Requirement | C5: Category | D5: Scenario | E5: Expected | F5: Actual | G5: Method | H5: Priority | I5: Status
A6: M4-TC-010 | B6: M7-Q01 | C6: Data quality | D6: Raw university records | E6: 1120 | F6: 1120 | G6: Automated | H6: Critical | I6: PASS
A7: M4-TC-011 | B7: M7-Q02 | C7: Data quality | D7: Raw source fields | E7: 42 | F7: 42 | G7: Automated | H7: High | I7: PASS
A8: M4-TC-012 | B8: M7-Q03 | C8: Data quality | D8: Country coverage | E8: 93 | F8: 93 | G8: Automated | H8: Critical | I8: PASS
A9: M4-TC-013 | B9: M7-Q04 | C9: Data quality | D9: Regional coverage | E9: 5 | F9: 5 | G9: Automated | H9: Critical | I9: PASS
A10: M4-TC-014 | B10: M7-Q05 | C10: Data quality | D10: Reporting-year scope | E10: 2026 only | F10: [2026] | G10: Automated | H10: Critical | I10: PASS
A11: M4-TC-015 | B11: M7-Q06 | C11: Data quality | D11: Source completeness | E11: >95% | F11: 98.176% | G11: Automated | H11: Critical | I11: PASS
A12: M4-TC-016 | B12: M7-Q07 | C12: Data quality | D12: Raw-audit completeness reconciliation | E12: 98.176 | F12: 98.176 | G12: Automated | H12: High | I12: PASS
A13: M4-TC-017 | B13: M7-Q08 | C13: Data quality | D13: Cleaned record preservation | E13: 1120 | F13: 1120 | G13: Automated | H13: Critical | I13: PASS
A14: M4-TC-018 | B14: M7-Q09 | C14: Data quality | D14: Cleaned field count | E14: 44 | F14: 44 | G14: Automated | H14: High | I14: PASS
A15: M4-TC-019 | B15: M7-Q10 | C15: Data quality | D15: Post-cleaning missingness | E15: <2% | F15: 1.5686% | G15: Automated | H15: Critical | I15: PASS
A16: M4-TC-020 | B16: M7-Q11 | C16: Data quality | D16: Cleaning-audit reconciliation | E16: 1.5686 | F16: 1.5686 | G16: Automated | H16: High | I16: PASS
... A25: M4-TC-029 | B25: M7-Q20 | C25: Data quality | D25: No fabricated publication totals | E25: no publication_count field | F25: [] | G25: Automated | H25: Critical | I25: PASS

Sheet Dashboard Functional
A1: Dashboard Functional and Binding Tests
A2: Page contracts, controls, visual field references, map roles, portability and report integration.
A5: Test ID | B5: Requirement | C5: Category | D5: Scenario | E5: Expected | F5: Actual | G5: Method | H5: Priority | I5: Status
A6: M4-TC-052 | B6: M7-D01 | C6: Dashboard page contract | D6: University Overview: correct order | E6: 1 | F6: 1 | G6: Automated | H6: Critical | I6: PASS
A7: M4-TC-053 | B7: M7-D02 | C7: Dashboard page contract | D7: University Overview: page width | E7: 1280 | F7: 1280 | G7: Automated | H7: High | I7: PASS
A8: M4-TC-054 | B8: M7-D03 | C8: Dashboard page contract | D8: University Overview: page height | E8: 1704 | F8: 1704 | G8: Automated | H8: High | I8: PASS
A9: M4-TC-055 | B9: M7-D04 | C9: Dashboard page contract | D9: University Overview: total visuals | E9: 21 | F9: 21 | G9: Automated | H9: Critical | I9: PASS
A10: M4-TC-056 | B10: M7-D05 | C10: Dashboard page contract | D10: University Overview: dropdown slicers | E10: 6 | F10: 6 | G10: Automated | H10: Critical | I10: PASS
A11: M4-TC-057 | B11: M7-D06 | C11: Dashboard page contract | D11: University Overview: KPI cards | E11: 4 | F11: 4 | G11: Automated | H11: Critical | I11: PASS
A12: M4-TC-058 | B12: M7-D07 | C12: Dashboard page contract | D12: University Overview: native navigator | E12: 1 | F12: 1 | G12: Automated | H12: Critical | I12: PASS
A13: M4-TC-059 | B13: M7-D08 | C13: Dashboard page contract | D13: University Overview: standard map | E13: 1 | F13: 1 | G13: Automated | H13: High | I13: PASS
A14: M4-TC-060 | B14: M7-D09 | C14: Dashboard page contract | D14: University Overview: no inactive projections | E14: 0 | F14: 0 | G14: Automated | H14: Critical | I14: PASS
A15: M4-TC-061 | B15: M7-D10 | C15: Dashboard page contract | D15: University Overview: unique visual identifiers | E15: 21 | F15: 21 | G15: Automated | H15: High | I15: PASS
A16: M4-TC-062 | B16: M7-D11 | C16: Dashboard page contract | D16: University Overview: KPI measures are bound | E16: 4 | F16: 4 | G16: Automated | H16: Critical | I16: PASS
... A217: M4-TC-263 | B217: M7-S08 | C217: Semantic model | D217: Single denormalized university table | E217: 1 | F217: 1 | G217: Automated | H217: High | I217: PASS

Sheet UAT Cases
A1: User Acceptance Test Register
A2: Observed Power BI behaviour corroborated by user confirmation, supplied screenshots and structural bindings.
A5: Test ID | B5: Requirement | C5: Category | D5: Scenario | E5: Expected | F5: Actual | G5: Method | H5: Priority | I5: Status
A6: M4-TC-267 | B6: M7-UAT | C6: User acceptance testing | D6: Open the PBIP project in current Power BI Desktop | E6: Project opens without report-definition error | F6: User confirmed working build | G6: Manual UAT / structural corroboration | H6: High | I6: PASS
A7: M4-TC-268 | B7: M7-UAT | C7: User acceptance testing | D7: Refresh the embedded Import model once | E7: All 1,120 records load without a local-file credential prompt | F7: Embedded model and populated dashboard confirmed | G7: Manual UAT / structural corroboration | H7: High | I7: PASS
A8: M4-TC-269 | B8: M7-UAT | C8: User acceptance testing | D8: University Overview KPI cards | E8: 1,120 universities; 93 countries; average score 57.1; maximum 100.0 | F8: Values visible in supplied Power BI screenshot | G8: Manual UAT / structural corroboration | H8: High | I8: PASS
A9: M4-TC-270 | B9: M7-UAT | C9: User acceptance testing | D9: Research Analytics KPI cards | E9: 50.2 impact; 46.4 productivity; 59.9 quality; 33.0 citations | F9: Values visible in supplied Power BI screenshot | G9: Manual UAT / structural corroboration | H9: High | I9: PASS
A10: M4-TC-271 | B10: M7-UAT | C10: User acceptance testing | D10: Student Analytics KPI cards | E10: 25K population; 17.3 students/staff; 14.6% international; 36.6 diversity | F10: Values visible in supplied Power BI screenshot | G10: Manual UAT / structural corroboration | H10: High | I10: PASS
A11: M4-TC-272 | B11: M7-UAT | C11: User acceptance testing | D11: Country Comparison KPI cards | E11: 93 countries; 1,120 universities; 389 improved; 428 declined | F11: Values visible in supplied Power BI screenshot | G11: Manual UAT / structural corroboration | H11: High | I11: PASS
A12: M4-TC-273 | B12: M7-UAT | C12: User acceptance testing | D12: University Overview charts | E12: Donut, regional benchmark, rank movement and scorecard display data | F12: Visuals visible in supplied screenshot | G12: Manual UAT / structural corroboration | H12: High | I12: PASS
A13: M4-TC-274 | B13: M7-UAT | C13: User acceptance testing | D13: Research Analytics charts | E13: Scatter, treemap, regional comparison and institution ranking display data | F13: Visuals visible in supplied screenshot | G13: Manual UAT / structural corroboration | H13: High | I13: PASS
A14: M4-TC-275 | B14: M7-UAT | C14: User acceptance testing | D14: Student Analytics charts | E14: Scatter, size mix, diversity benchmark, gauge and matrix display data | F14: Visuals visible in supplied screenshot | G14: Manual UAT / structural corroboration | H14: High | I14: PASS
A15: M4-TC-276 | B15: M7-UAT | C15: User acceptance testing | D15: Country Comparison charts | E15: Performance, employability, waterfall, matrix and decomposition display data | F15: Visuals visible in supplied screenshot | G15: Manual UAT / structural corroboration | H15: High | I15: PASS
A16: M4-TC-277 | B16: M7-UAT | C16: User acceptance testing | D16: Standard map rendering | E16: One map is available per dashboard after enabling Map/Filled Map security option | F16: Map visuals visible in supplied screenshots | G16: Manual UAT / structural corroboration | H16: High | I16: PASS
... A25: M4-TC-286 | B25: M7-UAT | C25: User acceptance testing | D25: Reopen saved PBIX | E25: Dashboard remains populated without repeating first-load setup | F25: User previously confirmed ongoing PBIX workflow | G25: Manual UAT / structural corroboration | H25: High | I25: PASS

Sheet KPI Reconciliation
A1: Six-KPI Reconciliation Evidence
A2: All six engineered KPIs reproduce exactly for every one of the 1,120 universities.
A5: KPI | B5: Rows Checked | C5: Matching Rows | D5: Accuracy | E5: Maximum Difference | F5: Status | G5: Formula Basis | H5: Interpretation
A6: KPI_Global_Ranking_Score | B6: 1120 | C6: 1120 | D6: 1 | E6: 1.4210855e-14 | F6: PASS | G6: AVERAGE(QS normalized, THE normalized) | H6: Combined ranking strength; higher is better.
A7: KPI_Research_Impact_Score | B7: 1120 | C7: 1120 | D7: 1 | E7: 1.4210855e-14 | F7: PASS | G7: 35% citations + 45% quality + 20% industry | H7: Research influence and practical impact.
A8: KPI_Faculty_to_Student_Ratio | B8: 1120 | C8: 1120 | D8: 1 | E8: 9.7144515e-17 | F8: PASS | G8: 1 / Students-to-Staff Ratio | H8: Faculty availability per student.
A9: KPI_International_Student_Percentage | B9: 1120 | C9: 1120 | D9: 1 | E9: 3.5527137e-15 | F9: PASS | G9: International student share × 100 | H9: International participation in percentage points.
A10: KPI_Academic_Reputation_Score | B10: 1120 | C10: 1120 | D10: 1 | E10: 0 | F10: PASS | G10: Supplied academic reputation score | H10: Source-aligned reputation measure.
A11: KPI_Research_Productivity_Index | B11: 1120 | C11: 1120 | D11: 1 | E11: 1.4210855e-14 | F11: PASS | G11: 30% quality + 25% environment + 20% citations + 15% network + 10% industry | H11: Research productivity proxy; not publication totals.
A14: LIMITATION CONTROL: The source contains no publication-count field. The Research Productivity Index is explicitly documented as a weighted indicator proxy and no publication totals are fabricated.

Sheet Dashboard Inventory
A1: Approved Dashboard Release Inventory
A2: Exact structure of the preserved 5-page, 110-visual, standard-map Power BI release.
A5: Page | B5: Width | C5: Height | D5: Visuals | E5: Data Visuals | F5: KPI Cards | G5: Slicers | H5: Navigator | I5: Map | J5: Active Bindings | K5: Inactive | L5: KPI Measures
A6: University Overview | B6: 1280 | C6: 1704 | D6: 21 | E6: 18 | F6: 4 | G6: 6 | H6: 1 | I6: 1 | J6: 56 | K6: 0 | L6: Highest Global Score; Average Global Score; Country Count; University Count
A7: Research Analytics | B7: 1280 | C7: 1704 | D7: 21 | E7: 18 | F7: 4 | G7: 6 | H7: 1 | I7: 1 | J7: 59 | K7: 0 | L7: Average Citations per Faculty; Average Research Productivity; Average Research Quality; Average Research Impact
A8: Student Analytics | B8: 1280 | C8: 1704 | D8: 21 | E8: 18 | F8: 4 | G8: 6 | H8: 1 | I8: 1 | J8: 58 | K8: 0 | L8: Average Student Population; Average Student Diversity; International Students %; Average Students to Staff
A9: Country Comparison | B9: 1280 | C9: 1704 | D9: 21 | E9: 18 | F9: 4 | G9: 6 | H9: 1 | I9: 1 | J9: 59 | K9: 0 | L9: Declined Universities; Country Count; Improved Universities; University Count
A10: Executive Command Center | B10: 1280 | C10: 2204 | D10: 26 | E10: 23 | F10: 6 | G10: 6 | H10: 1 | I10: 1 | J10: 78 | K10: 0 | L10: Average Sustainability; University Count; Country Count; International Students %; Average Global Score; Average Research Impact
A13: Visual Type | B13: Count | C13: Purpose / Control
A14: card | B14: 22 | C14: Primary KPI callouts
A15: clusteredBarChart | B15: 4 | C15: Institution/country ranking
A16: clusteredColumnChart | B16: 4 | C16: Regional benchmarking
A17: decompositionTreeVisual | B17: 2 | C17: Interactive contribution analysis
A18: donutChart | B18: 3 | C18: Composition
A19: funnel | B19: 2 | C19: Institution scale
A20: gauge | B20: 2 | C20: Benchmark target
A21: hundredPercentStackedBarChart | B21: 2 | C21: Share composition
A22: lineClusteredColumnComboChart | B22: 2 | C22: Multi-measure comparison
A23: map | B23: 5 | C23: Country-level geographic comparison
A24: pageNavigator | B24: 5 | C24: Native navigation
A25: pieChart | B25: 1 | C25: Status composition
... A33: waterfallChart | B33: 2 | C33: Positive/negative rank movement

Sheet Defect Log
A1: Defect and Resolution Log
A2: Historical issues are retained as regression evidence; all release-blocking defects are closed.
A5: Defect ID | B5: Observed Issue | C5: Root Cause | D5: Corrective Action | E5: Regression Test | F5: Priority | G5: Status | H5: Detected | I5: Closed | J5: Residual Note
A6: DEF-001 | B6: PBIP opened with blank visuals | C6: PBIP project had no processed cache.abf | D6: Embedded Import query retained; refresh-once and PBIX save workflow documented | E6: M7-S03 / UAT refresh | F6: Critical | G6: CLOSED | H6: 2026-08-21 | I6: 2026-08-21 | J6: First PBIP refresh remains a platform requirement
A7: DEF-002 | B7: KPI cards displayed empty containers | C7: Modern card bindings were ignored by Desktop runtime | D7: Replaced with stable single-measure card visual | E7: M7-D06 / M7-D11 | F7: Critical | G7: CLOSED | H7: 2026-08-21 | I7: 2026-08-21 | J7: All 22 cards now use active Values bindings
A8: DEF-003 | B8: Charts had headings but no numeric values | C8: Numeric projections were inactive | D8: Activated every numeric projection | E8: M7-D09 / M7-D16 | F8: Critical | G8: CLOSED | H8: 2026-08-21 | I8: 310/310 bindings active
A9: DEF-004 | B9: Scorecards showed headers without rows | C9: Incorrect table binding structure | D9: Rebuilt as pivot matrices with Rows and Values roles | E9: M7-F01 | F9: High | G9: CLOSED | H9: 2026-08-21 | I9: Matrix fields validated against model
A10: DEF-005 | B10: Azure Maps requested Power BI sign-in | C10: Azure Maps visual has an account/tenant gate | D10: Replaced five Azure Maps with standard Bing map visuals | E10: M7-D22 / M7-M01 | F10: Critical | G10: CLOSED | H10: 2026-08-25 | I10: Internet and Map/Filled Map security option still required
A11: DEF-006 | B11: Navigation seemed inactive in edit mode | C11: Power BI Desktop requires Ctrl+click in editing mode | D11: Added explicit header instruction and user guide | E11: UAT navigation cases | F11: Medium | G11: CLOSED | H11: 2026-08-21 | I11: Single click works in reading mode
A12: DEF-007 | B12: Risk of broken Excel file path on another computer | C12: Traditional File.Contents path would be machine-specific | D12: Embedded compressed Import data in the semantic model | E12: M7-S03 / M7-S04 | F12: Critical | G12: CLOSED | H12: 2026-08-21 | I12: No machine-specific data path remains
A13: DEF-008 | B13: Blank white visual containers | C13: Unsupported or unbound visual definitions | D13: Removed empty containers and used native bound visuals | E13: M7-D04 / M7-F01 | F13: High | G13: CLOSED | H13: 2026-08-21 | I13: 110 report elements have valid definitions
A14: DEF-009 | B14: Map could be disabled locally | C14: Power BI Security setting can disable Map/Filled Map | D14: Added exact enable-and-restart instruction | E14: UAT standard map case | F14: Medium | G14: CLOSED | H14: 2026-08-25 | I14: Configuration dependency is documented
A15: DEF-010 | B15: Automatic page refresh expected for Excel Import data | C15: Power BI Import mode does not support automatic page refresh | D15: Documented manual refresh and refresh-on-open expectations | E15: Operations guide refresh SOP | F15: Medium | G15: CLOSED | H15: 2026-08-21 | I15: No unsupported automation claim is made

Sheet Risk Register
A1: Operational Risk Register
A2: Known data, platform, usability and maintenance risks with assigned controls and residual ratings.
A5: Risk ID | B5: Risk | C5: Likelihood | D5: Impact | E5: Inherent Rating | F5: Primary Control | G5: Residual Rating | H5: Owner | I5: Review Trigger | J5: Status
A6: RSK-01 | B6: Bing map tiles unavailable without internet | C6: Medium | D6: Low | E6: Medium | F6: All non-map analytics remain functional; document internet dependency | G6: Low | H6: Report owner | I6: Map does not render | J6: CONTROLLED
A7: RSK-02 | B7: Map/Filled Map security option disabled | C7: Medium | D7: Medium | E7: Medium | F7: Enable option under Global > Security and restart Desktop | G7: Low | H7: Desktop user | I7: Blank map visual | J7: CONTROLLED
A8: RSK-03 | B8: First PBIP refresh omitted | C8: Medium | D8: High | E8: High | F8: START_HERE launcher and first-open checklist | G8: Low | H8: Desktop user | I8: Grey refresh banner | J8: CONTROLLED
A9: RSK-04 | B9: Old PBIX opened instead of approved build | C9: Medium | D9: High | E9: High | F9: Release naming, checksum and archive isolation | G9: Low | H9: Project owner | I9: Visual counts do not match 110 | J9: CONTROLLED
A10: RSK-05 | B10: Source schema changes during future refresh | C10: Low | D10: High | E10: High | F10: Run Module 7 validator before release; preserve 35 model fields | G10: Medium | H10: Data owner | I10: Column addition/removal | J10: MONITORED
A11: RSK-06 | B11: 2026 snapshot misread as multi-year trend | C11: Medium | D11: High | E11: High | F11: Explicit 2026-only limitation on reports and documentation | G11: Low | H11: Presenter | I11: Trend interpretation request | J11: CONTROLLED
A12: RSK-07 | B12: Research productivity misread as publication volume | C12: Medium | D12: High | E12: High | F12: Document weighted proxy formula and no-publication constraint | G12: Low | H12: Presenter | I12: Publication-count question | J12: CONTROLLED
A13: RSK-08 | B13: Country geocoding ambiguity | C13: Low | D13: Medium | E13: Medium | F13: Country data category and standardized country names | G13: Low | H13: Data owner | I13: Unexpected map placement | J13: MONITORED
A14: RSK-09 | B14: Hidden slicer state creates confusing comparison | C14: Medium | D14: Medium | E14: Medium | F14: Clear slicers before baseline comparison; verify headline totals | G14: Low | H14: Analyst | I14: KPI total differs from baseline | J14: CONTROLLED
A15: RSK-10 | B15: Power BI version changes PBIR runtime behaviour | C15: Low | D15: High | E15: High | F15: Open and regression-test in current Desktop before submission | G15: Medium | H15: Report owner | I15: Desktop upgrade | J15: MONITORED
A16: RSK-11 | B16: Large page requires scrolling | C16: Medium | D16: Low | E16: Low | F16: Fit-to-width layout and clear section order | G16: Low | H16: Presenter | I16: User misses lower visual | J16: ACCEPTED
A17: RSK-12 | B17: Colour-based interpretation may affect accessibility | C17: Medium | D17: Medium | E17: Medium | F17: Use labels, legends, tooltips and tables in addition to colour | G17: Low | H17: Report owner | I17: Accessibility review | J17: CONTROLLED

Sheet Release Checklist
A1: Milestone 4 Release Checklist
A2: Submission gates for data, dashboard, documentation, portability, reproducibility and handover.
A5: Gate ID | B5: Release Gate | C5: Acceptance Criterion | D5: Evidence | E5: Owner | F5: Status | G5: Remarks
A6: REL-01 | B6: Approved ZIP integrity | C6: Checksum matches approved build | D6: module7_validation.json | E6: QA owner | F6: PASS | G6: 98dd2ed7bdae98fabe661d68af729c3cdb8c3f1d5ae097d94492813ba1593a12
A7: REL-02 | B7: Dataset population | C7: 1,120 universities | D7: university_final_dataset.csv | E7: Data owner | F7: PASS | G7: Exact
A8: REL-03 | B8: Country and region coverage | C8: 93 countries; 5 regions | D8: module7_validation.json | E8: Data owner | F8: PASS | G8: Exact
A9: REL-04 | B9: Reporting-year control | C9: 2026 only | D9: Data Quality sheet | E9: Data owner | F9: PASS | G9: No fabricated years
A10: REL-05 | B10: Raw completeness | C10: >95% | D10: raw_data_profile.json | E10: Data owner | F10: PASS | G10: 98.176%
A11: REL-06 | B11: Cleaned missingness | C11: <2% | D11: cleaning_audit.json | E11: Data owner | F11: PASS | G11: 1.5686%
A12: REL-07 | B12: Duplicate control | C12: 0 duplicate institution-country-year keys | D12: Data Quality sheet | E12: QA owner | F12: PASS | G12: 0
A13: REL-08 | B13: KPI reconciliation | C13: 6 KPIs × 1,120 rows at 100% | D13: KPI Reconciliation sheet | E13: QA owner | F13: PASS | G13: 6,720 exact comparisons
A14: REL-09 | B14: Page inventory | C14: Five pages in approved order | D14: Dashboard Inventory sheet | E14: Report owner | F14: PASS | G14: Exact
A15: REL-10 | B15: Visual inventory | C15: 110 visuals; 95 data visuals | D15: Dashboard Inventory sheet | E15: Report owner | F15: PASS | G15: Exact
A16: REL-11 | B16: KPI cards | C16: 22 stable bound cards | D16: Dashboard Functional sheet | E16: Report owner | F16: PASS | G16: No unbound cards
... A35: REL-30 | B35: Final archive | C35: Archive integrity check passes | D35: Final ZIP | E35: Release owner | F35: PASS | G35: Verified at packaging

Sheet Data Dictionary
A1: Final Dataset Data Dictionary
A2: 1120 rows, 50 fields, reporting year 2026; source and derived roles are explicitly distinguished.
A5: Field | B5: Role | C5: Data Type | D5: Non-null | E5: Missing | F5: Missing % | G5: Unique | H5: Minimum | I5: Maximum | J5: Examples | K5: Definition
A6: Rank_QS | B6: Source field | C6: object | D6: 1120 | E6: 0 | F6: 0 | G6: 372 | J6: 1; 2; 3 | K6: Rank QS from the supplied QS/THE dataset.
A7: Previous_Rank | B7: Source field | C7: object | D7: 1062 | E7: 58 | F7: 0.051786 | G7: 354 | J7: 1; 2; 6 | K7: Previous Rank from the supplied QS/THE dataset.
A8: Name | B8: Source field | C8: object | D8: 1120 | E8: 0 | F8: 0 | G8: 1120 | J8: Massachusetts Institute of Technology (MIT); Imperial College London; Stanford University | K8: Standardized university name used as the institutional label.
A9: Region | B9: Source field | C9: object | D9: 1120 | E9: 0 | F9: 0 | G9: 5 | J9: Americas; Europe; Asia | K9: Geographic region used for dashboard grouping.
A10: Size | B10: Source field | C10: object | D10: 1120 | E10: 0 | F10: 0 | G10: 4 | J10: M; L; XL | K10: Institution size category from the supplied source.
A11: Focus | B11: Source field | C11: object | D11: 1120 | E11: 0 | F11: 0 | G11: 4 | J11: CO; FO; FC | K11: Institutional subject-focus category from the supplied source.
A12: Research | B12: Source field | C12: object | D12: 1120 | E12: 0 | F12: 0 | G12: 3 | J12: VH; HI; MD | K12: Research-activity category from the supplied source.
A13: Status | B13: Source field | C13: object | D13: 1120 | E13: 0 | F13: 0 | G13: 4 | J13: Private not for Profit; Public; Not reported | K13: Institution ownership/status category from the supplied source.
A14: Academic_Reputation_Score | B14: Source field | C14: float64 | D14: 1120 | E14: 0 | F14: 0 | G14: 495 | H14: 1 | I14: 100 | J14: 100.0; 99.6; 99.7 | K14: Academic Reputation Score from the supplied QS/THE dataset.
A15: Academic_Reputation_Rank | B15: Source field | C15: object | D15: 1120 | E15: 0 | F15: 0 | G15: 576 | J15: 4; 22; 5 | K15: Academic Reputation Rank from the supplied QS/THE dataset.
A16: Employer_Reputation_Score | B16: Source field | C16: float64 | D16: 1120 | E16: 0 | F16: 0 | G16: 535 | H16: 1 | I16: 100 | J16: 100.0; 96.3; 98.2 | K16: Employer Reputation Score from the supplied QS/THE dataset.
A17: Employer_Reputation_Rank | B17: Source field | C17: object | D17: 1120 | E17: 0 | F17: 0 | G17: 565 | J17: 2; 9; 3 | K17: Employer Reputation Rank from the supplied QS/THE dataset.
A18: Faculty_Student_Ratio_Score | B18: Source field | C18: float64 | D18: 1120 | E18: 0 | F18: 0 | G18: 555 | H18: 1 | I18: 100 | J18: 100.0; 99.3; 98.3 | K18: Faculty Student Ratio Score from the supplied QS/THE dataset.
A19: Faculty_Student_Ratio_Rank | B19: Source field | C19: object | D19: 1120 | E19: 0 | F19: 0 | G19: 571 | J19: 16; 42; 17 | K19: Faculty Student Ratio Rank from the supplied QS/THE dataset.
A20: Citations_per_Faculty_Score | B20: Source field | C20: float64 | D20: 1120 | E20: 0 | F20: 0 | G20: 569 | H20: 1.2 | I20: 100 | J20: 100.0; 95.0; 99.7 | K20: Citations per Faculty Score from the supplied QS/THE dataset.
A21: Citations_per_Faculty_Rank | B21: Source field | C21: object | D21: 1120 | E21: 0 | F21: 0 | G21: 648 | J21: 7; 69; 24 | K21: Citations per Faculty Rank from the supplied QS/THE dataset.
A22: International_Faculty_Score | B22: Source field | C22: float64 | D22: 1073 | E22: 47 | F22: 0.041964 | G22: 522 | H22: 1 | I22: 100 | J22: 100.0; 94.2; 98.8 | K22: International Faculty Score from the supplied QS/THE dataset.
A23: International_Faculty_Rank | B23: Source field | C23: object | D23: 1073 | E23: 47 | F23: 0.041964 | G23: 628 | J23: 63; 74; 188 | K23: International Faculty Rank from the supplied QS/THE dataset.
A24: International_Student_Score | B24: Source field | C24: float64 | D24: 1100 | E24: 20 | F24: 0.017857 | G24: 540 | H24: 1 | I24: 100 | J24: 91.6; 100.0; 73.5 | K24: International Student Score from the supplied QS/THE dataset.
A25: International_Student_Rank | B25: Source field | C25: object | D25: 1100 | E25: 20 | F25: 0.017857 | G25: 625 | J25: 153; 35; 261 | K25: International Student Rank from the supplied QS/THE dataset.
A26: International_Students_Diversity_Score | B26: Source field | C26: float64 | D26: 1100 | E26: 20 | F26: 0.017857 | G26: 560 | H26: 1 | I26: 100 | J26: 92.3; 100.0; 76.1 | K26: International Students Diversity Score from the supplied QS/THE dataset.
A27: International_Students_Diversity_Rank | B27: Source field | C27: object | D27: 1100 | E27: 20 | F27: 0.017857 | G27: 635 | J27: 130; 22; 230 | K27: International Students Diversity Rank from the supplied QS/THE dataset.
A28: International_Research_Network_Score | B28: Source field | C28: float64 | D28: 1120 | E28: 0 | F28: 0 | G28: 647 | H28: 3.3 | I28: 100 | J28: 94.1; 97.5; 96.5 | K28: International Research Network Score from the supplied QS/THE dataset.
A29: International_Research_Network_Rank | B29: Source field | C29: object | D29: 1120 | E29: 0 | F29: 0 | G29: 661 | J29: 98; 28; 49 | K29: International Research Network Rank from the supplied QS/THE dataset.
A30: Employment_Outcomes_Score | B30: Source field | C30: float64 | D30: 1120 | E30: 0 | F30: 0 | G30: 555 | H30: 1.2 | I30: 100 | J30: 100.0; 95.9; 95.0 | K30: Employment Outcomes Score from the supplied QS/THE dataset.
A31: Employment_Outcomes_Rank | B31: Source field | C31: object | D31: 1120 | E31: 0 | F31: 0 | G31: 630 | J31: 7; 68; 2 | K31: Employment Outcomes Rank from the supplied QS/THE dataset.
A32: Sustainability_Score | B32: Source field | C32: float64 | D32: 1118 | E32: 2 | F32: 0.001786 | G32: 583 | H32: 3 | I32: 100 | J32: 93.8; 98.3; 95.4 | K32: Sustainability Score from the supplied QS/THE dataset.
A33: Sustainability_Rank | B33: Source field | C33: object | D33: 1118 | E33: 2 | F33: 0.001786 | G33: 363 | J33: 33; 7=; 19= | K33: Sustainability Rank from the supplied QS/THE dataset.
A34: QS_Overall_Score | B34: Source field | C34: float64 | D34: 583 | E34: 537 | F34: 0.479464 | G34: 355 | H34: 25.1 | I34: 100 | J34: 100.0; 99.4; 98.9 | K34: QS Overall Score from the supplied QS/THE dataset.
A35: Rank_THE | B35: Source field | C35: int64 | D35: 1120 | E35: 0 | F35: 0 | G35: 1116 | H35: 1 | I35: 2171 | J35: 2; 8; 5 | K35: Rank THE from the supplied QS/THE dataset.
A36: Student_Population | B36: Source field | C36: int64 | D36: 1120 | E36: 0 | F36: 0 | G36: 1100 | H36: 942 | I36: 281032 | J36: 11703; 21340; 17422 | K36: Student Population from the supplied QS/THE dataset.
A37: Students_to_Staff_Ratio | B37: Source field | C37: float64 | D37: 1120 | E37: 0 | F37: 0 | G37: 289 | H37: 3.4 | I37: 84.5 | J37: 7.7; 12.1; 5.9 | K37: Students to Staff Ratio from the supplied QS/THE dataset.
A38: International_Students | B38: Source field | C38: float64 | D38: 1120 | E38: 0 | F38: 0 | G38: 66 | H38: 0 | I38: 0.81 | J38: 0.33; 0.6; 0.25 | K38: International Students from the supplied QS/THE dataset.
A39: Female_to_Male_Ratio | B39: Source field | C39: object | D39: 1120 | E39: 0 | F39: 0 | G39: 64 | J39: 43 : 57; 48 : 52; 52 : 48 | K39: Female to Male Ratio from the supplied QS/THE dataset.
A40: THE_Overall_Score | B40: Source field | C40: float64 | D40: 1120 | E40: 0 | F40: 0 | G40: 1116 | H40: 13.3725 | I40: 98.21 | J40: 97.6735; 94.689; 97.151 | K40: THE Overall Score from the supplied QS/THE dataset.
A41: Teaching | B41: Source field | C41: float64 | D41: 1120 | E41: 0 | F41: 0 | G41: 445 | H41: 10.4 | I41: 99.2 | J41: 99.2; 90.6; 97.5 | K41: Teaching from the supplied QS/THE dataset.
A42: Research_Environment | B42: Source field | C42: float64 | D42: 1120 | E42: 0 | F42: 0 | G42: 446 | H42: 6.8 | I42: 100 | J42: 95.3; 94.9; 97.4 | K42: Research Environment from the supplied QS/THE dataset.
...

Sheet Evidence Index
A1: Milestone 4 Evidence Index
A2: Where every QA, technical, operational and release artifact is stored inside the final package.
A5: Evidence ID | B5: Artifact | C5: Module | D5: Purpose | E5: Format | F5: Generated By | G5: Location
A6: EVD-001 | B6: Approved Power BI release | C6: Modules 4-6 reference | D6: Exact working dashboard build preserved unchanged | E6: ZIP | F6: Approved release process | G6: APPROVED_POWER_BI_RELEASE/
A7: EVD-002 | B7: Module 7 validation | C7: Module 7 | D7: Machine-readable 286-test release evidence | E7: JSON | F7: validate_milestone4.py | G7: MODULE_07_QA_TESTING/evidence/
A8: EVD-003 | B8: Detailed test results | C8: Module 7 | D8: One row per executed test | E8: CSV | F8: validate_milestone4.py | G8: MODULE_07_QA_TESTING/evidence/
A9: EVD-004 | B9: Dashboard inventory | C9: Module 7 | D9: Page, visual, map, card, slicer and binding inventory | E9: JSON | F9: validate_milestone4.py | G9: MODULE_07_QA_TESTING/evidence/
A10: EVD-005 | B10: QA master workbook | C10: Module 7 | D10: Traceability, tests, UAT, defects, risks and release gates | E10: XLSX | F10: build_qa_master.mjs | G10: MODULE_07_QA_TESTING/
A11: EVD-006 | B11: Detailed testing report | C11: Module 7 | D11: Formal QA narrative and release recommendation | E11: DOCX/PDF | F11: build_milestone4_documents.py | G11: MODULE_07_QA_TESTING/
A12: EVD-007 | B12: Final technical documentation | C12: Module 8 | D12: Architecture, analytics, governance and handover | E12: DOCX/PDF | F12: build_milestone4_documents.py | G12: MODULE_08_FINAL_HANDOVER/
A13: EVD-008 | B13: Operations and maintenance guide | C13: Module 8 | D13: Beginner-safe open, refresh, map, backup and update procedures | E13: DOCX/PDF | F13: build_milestone4_documents.py | G13: MODULE_08_FINAL_HANDOVER/
A14: EVD-009 | B14: Final presentation | C14: Module 8 | D14: Milestone 4 defense presentation | E14: PPTX | F14: build_milestone4_presentation.mjs | G14: MODULE_08_FINAL_HANDOVER/
A15: EVD-010 | B15: Presentation readout | C15: Module 8 | D15: Speaker script for the final deck | E15: DOCX/PDF | F15: build_milestone4_documents.py | G15: MODULE_08_FINAL_HANDOVER/
A16: EVD-011 | B16: Reference datasets | C16: Modules 1-3 reference | D16: Raw, cleaned and KPI dataset evidence | E16: CSV/XLSX/JSON | F16: Upstream pipeline | G16: REFERENCE_DATA/
A17: EVD-012 | B17: Release manifest | C17: Module 8 | D17: SHA-256 and archive completeness | E17: TXT/CSV/JSON | F17: package_release.py | G17: MANIFEST/

Sheet UAT Sign-Off
A1: User Acceptance and Release Sign-Off
A2: Complete the named approval fields when submitting or transferring ownership. All objective release gates are already populated from the QA evidence.
A4: Acceptance Criterion | B4: Expected | C4: Observed | D4: Status
A5: Dashboard opens and refreshes | B5: No local path or credential prompt | C5: Embedded Import model; refresh-once workflow | D5: PASS
A6: Core dataset totals | B6: 1,120 universities; 93 countries; 5 regions | C6: Exact | D6: PASS
A7: KPI calculations | B7: 100% reconciliation across six KPIs | C7: 6,720 exact row-KPI comparisons | D7: PASS
A8: KPI card rendering | B8: 22 visible and bound cards | C8: 22 active card definitions | D8: PASS
A9: Filters and navigation | B9: Six slicers and one navigator per page | C9: 30 slicers and five navigators | D9: PASS
A10: Map analysis | B10: One standard map per dashboard | C10: Five map definitions; no Azure Map | D10: PASS
A11: Release defects | B11: No open critical defect | C11: 0 | D11: PASS
A12: Documentation | B12: QA, technical, operations and presentation files | C12: Included in Milestone 4 package | D12: PASS
A15: FORMAL APPROVAL
A17: Project Owner | D17: Reviewer | G17: Date
A19: Decision | B19: APPROVED | D19: Signature | G19: Version | H19: Milestone 4 Final
A22: Reviewer comments / approval conditions:
